Workbook
Name ASH: #N/A
Name CALCIUM: #N/A
Name CARBOHYDRT: #N/A
Name CHOLESTRL: #N/A
Name Conferencia: #REF!
Name Consulta: #REF!
Name Consulta1: #REF!
Name COPPER: #N/A
Name DS: #REF!
Name ENERG_KCAL: #N/A
Name FA_MONO: #N/A
Name FA_POLY: #N/A
Name FA_SAT: #N/A
Name FIBER_TD: #N/A
Name FOLATE: #N/A
Name FS: #REF!
Name FSDFG: #REF!
Name GMWT_1: #N/A
Name GMWT_2: #N/A
Name GMWT_DESC1: #N/A
Name GMWT_DESC2: #N/A
Name IRON: #N/A
Name karilene: #REF!
Name MAGNESIUM: #N/A
Name MANGANESE: #N/A
Name MERDA: #REF!
Name NDB_NO: #N/A
Name NIACIN: #N/A
Name NUTR_DEF: #REF!
Name PANTO_ACID: #N/A
Name PHOSPHORUS: #N/A
Name POTASSIUM: #N/A
Name PROTEIN: #N/A
Name REFUSE_PCT: #N/A
Name ResulAcGr_Tabela_de_referência_cruzada: #REF!
Name RIBOFLAVIN: #N/A
Name SABADO: #REF!
Name SELENIUM: #N/A
Name semana: #REF!
Name SHRT_DESC: #N/A
Name SODIUM: #N/A
Name TACO_ALIMENTOS_MS: #REF!
Name teste: #REF!
Name THIAMIN: #N/A
Name TOT_LIPID: #N/A
Name VIT_A: #N/A
Name VIT_B12: #N/A
Name VIT_B6: #N/A
Name VIT_C: #N/A
Name VIT_E: #N/A
Name WATER: #N/A
Name ZINC: #N/A

Sheet plan1
A1: id_prato | B1: CARDAPIO | C1: id_ingrediente | D1: ALIMENTO | E1: PER_CAPITA | H1: prato_id | I1: ingrediente_id | J1: quantidade_g
A2: =_xlfn.XLOOKUP(B2,pratos!B:B,pratos!A:A,"não") -> 39 | B2: Abacaxi | C2: =_xlfn.XLOOKUP(D2,ingredientes!B:B,ingredientes!A:A,"não") -> 2 | D2: Abacaxi cru | E2: 100 | H2: =A2 -> 39 | I2: =C2 -> 2 | J2: =E2 -> 100 | K2: =H2+I2 -> 41
A3: =_xlfn.XLOOKUP(B3,pratos!B:B,pratos!A:A,"não") -> 40 | B3: Abóbora refogada | C3: =_xlfn.XLOOKUP(D3,ingredientes!B:B,ingredientes!A:A,"não") -> 6 | D3: Abóbora moranga refogada, sem sal | E3: 100 | H3: =A3 -> 40 | I3: =C3 -> 6 | J3: =E3 -> 100 | K3: =H3+I3 -> 46
A4: =_xlfn.XLOOKUP(B4,pratos!B:B,pratos!A:A,"não") -> 40 | B4: Abóbora refogada | C4: =_xlfn.XLOOKUP(D4,ingredientes!B:B,ingredientes!A:A,"não") -> 6 | D4: Abóbora moranga refogada, sem sal | E4: 50 | H4: =A4 -> 40 | I4: =C4 -> 6 | J4: =E4 -> 50 | K4: =H4+I4 -> 46
A5: =_xlfn.XLOOKUP(B5,pratos!B:B,pratos!A:A,"não") -> 41 | B5: Abóbora Sautée | C5: =_xlfn.XLOOKUP(D5,ingredientes!B:B,ingredientes!A:A,"não") -> 6 | D5: Abóbora moranga refogada, sem sal | E5: 100 | H5: =A5 -> 41 | I5: =C5 -> 6 | J5: =E5 -> 100 | K5: =H5+I5 -> 47
A6: =_xlfn.XLOOKUP(B6,pratos!B:B,pratos!A:A,"não") -> 43 | B6: Abóbora Sautée com Bacon | C6: =_xlfn.XLOOKUP(D6,ingredientes!B:B,ingredientes!A:A,"não") -> 6 | D6: Abóbora moranga refogada, sem sal | E6: 100 | H6: =A6 -> 43 | I6: =C6 -> 6 | J6: =E6 -> 100 | K6: =H6+I6 -> 49
A7: =_xlfn.XLOOKUP(B7,pratos!B:B,pratos!A:A,"não") -> 43 | B7: Abóbora Sautée com Bacon | C7: =_xlfn.XLOOKUP(D7,ingredientes!B:B,ingredientes!A:A,"não") -> 44 | D7: Bacon | E7: 10 | H7: =A7 -> 43 | I7: =C7 -> 44 | J7: =E7 -> 10 | K7: =H7+I7 -> 87
A8: =_xlfn.XLOOKUP(B8,pratos!B:B,pratos!A:A,"não") -> 44 | B8: Abobrinha ao forno | C8: =_xlfn.XLOOKUP(D8,ingredientes!B:B,ingredientes!A:A,"não") -> 12 | D8: Abobrinha italiana refogada, sem sal | E8: 100 | H8: =A8 -> 44 | I8: =C8 -> 12 | J8: =E8 -> 100 | K8: =H8+I8 -> 56
A9: =_xlfn.XLOOKUP(B9,pratos!B:B,pratos!A:A,"não") -> 45 | B9: Abobrinha com coentro | C9: =_xlfn.XLOOKUP(D9,ingredientes!B:B,ingredientes!A:A,"não") -> 10 | D9: Abobrinha italiana ensopada, sem sal | E9: 100 | H9: =A9 -> 45 | I9: =C9 -> 10 | J9: =E9 -> 100 | K9: =H9+I9 -> 55
A10: =_xlfn.XLOOKUP(B10,pratos!B:B,pratos!A:A,"não") -> 45 | B10: Abobrinha com coentro | C10: =_xlfn.XLOOKUP(D10,ingredientes!B:B,ingredientes!A:A,"não") -> 150 | D10: Folha de coentro crua | E10: 5 | H10: =A10 -> 45 | I10: =C10 -> 150 | J10: =E10 -> 5 | K10: =H10+I10 -> 195
A11: =_xlfn.XLOOKUP(B11,pratos!B:B,pratos!A:A,"não") -> 46 | B11: Abobrinha cozida | C11: =_xlfn.XLOOKUP(D11,ingredientes!B:B,ingredientes!A:A,"não") -> 10 | D11: Abobrinha italiana ensopada, sem sal | E11: 100 | H11: =A11 -> 46 | I11: =C11 -> 10 | J11: =E11 -> 100 | K11: =H11+I11 -> 56
A12: =_xlfn.XLOOKUP(B12,pratos!B:B,pratos!A:A,"não") -> 47 | B12: Abobrinha em Lâminas com Bacon | C12: =_xlfn.XLOOKUP(D12,ingredientes!B:B,ingredientes!A:A,"não") -> 8 | D12: Abobrinha italiana cozida sem sal | E12: 90 | H12: =A12 -> 47 | I12: =C12 -> 8 | J12: =E12 -> 90 | K12: =H12+I12 -> 55
A13: =_xlfn.XLOOKUP(B13,pratos!B:B,pratos!A:A,"não") -> 48 | B13: Abobrinha em Lâminas com tempero verde | C13: =_xlfn.XLOOKUP(D13,ingredientes!B:B,ingredientes!A:A,"não") -> 8 | D13: Abobrinha italiana cozida sem sal | E13: 100 | H13: =A13 -> 48 | I13: =C13 -> 8 | J13: =E13 -> 100 | K13: =H13+I13 -> 56
... A1024: =_xlfn.XLOOKUP(B1024,pratos!B:B,pratos!A:A,"não") -> 447 | B1024: Vitamina HPHC | C1024: =_xlfn.XLOOKUP(D1024,ingredientes!B:B,ingredientes!A:A,"não") -> 323 | D1024: Vitamina HPHC | E1024: 160 | H1024: =A1024 -> 447 | I1024: =C1024 -> 323 | J1024: =E1024 -> 160 | K1024: =H1024+I1024 -> 770

Sheet plan1 (2)
A1: id_prato | B1: CARDAPIO | C1: id_ingrediente | D1: ALIMENTO | E1: PER_CAPITA | H1: prato_id | I1: ingrediente_id | J1: quantidade_g | M1: prato_id | N1: ingrediente_id | O1: quantidade_g
A2: =_xlfn.XLOOKUP(B2,pratos!B:B,pratos!A:A,"não") -> 39 | B2: Abacaxi | C2: =_xlfn.XLOOKUP(D2,ingredientes!B:B,ingredientes!A:A,"não") -> 2 | D2: Abacaxi cru | E2: 100 | H2: =A2 -> 39 | I2: =C2 -> 2 | J2: =E2 -> 100 | K2: =H2+I2 -> 41 | M2: 39 | N2: 2 | O2: 100 | Q2: =EXACT(H2,M2) -> TRUE | R2: =EXACT(I2,N2) -> TRUE | S2: =EXACT(J2,O2) -> TRUE
A3: =_xlfn.XLOOKUP(B3,pratos!B:B,pratos!A:A,"não") -> 40 | B3: Abóbora refogada | C3: =_xlfn.XLOOKUP(D3,ingredientes!B:B,ingredientes!A:A,"não") -> 6 | D3: Abóbora moranga refogada, sem sal | E3: 100 | H3: =A3 -> 40 | I3: =C3 -> 6 | J3: =E3 -> 100 | K3: =H3+I3 -> 46 | M3: 40 | N3: 6 | O3: 100 | Q3: =EXACT(H3,M3) -> TRUE | R3: =EXACT(I3,N3) -> TRUE | S3: =EXACT(J3,O3) -> TRUE
A4: =_xlfn.XLOOKUP(B4,pratos!B:B,pratos!A:A,"não") -> 41 | B4: Abóbora Sautée | C4: =_xlfn.XLOOKUP(D4,ingredientes!B:B,ingredientes!A:A,"não") -> 6 | D4: Abóbora moranga refogada, sem sal | E4: 100 | H4: =A4 -> 41 | I4: =C4 -> 6 | J4: =E4 -> 100 | K4: =H4+I4 -> 47 | M4: 41 | N4: 6 | O4: 100 | Q4: =EXACT(H4,M4) -> TRUE | R4: =EXACT(I4,N4) -> TRUE | S4: =EXACT(J4,O4) -> TRUE
A5: =_xlfn.XLOOKUP(B5,pratos!B:B,pratos!A:A,"não") -> 43 | B5: Abóbora Sautée com Bacon | C5: =_xlfn.XLOOKUP(D5,ingredientes!B:B,ingredientes!A:A,"não") -> 6 | D5: Abóbora moranga refogada, sem sal | E5: 100 | H5: =A5 -> 43 | I5: =C5 -> 6 | J5: =E5 -> 100 | K5: =H5+I5 -> 49 | M5: 43 | N5: 6 | O5: 100 | Q5: =EXACT(H5,M5) -> TRUE | R5: =EXACT(I5,N5) -> TRUE | S5: =EXACT(J5,O5) -> TRUE
A6: =_xlfn.XLOOKUP(B6,pratos!B:B,pratos!A:A,"não") -> 43 | B6: Abóbora Sautée com Bacon | C6: =_xlfn.XLOOKUP(D6,ingredientes!B:B,ingredientes!A:A,"não") -> 44 | D6: Bacon | E6: 10 | H6: =A6 -> 43 | I6: =C6 -> 44 | J6: =E6 -> 10 | K6: =H6+I6 -> 87 | M6: 43 | N6: 44 | O6: 10 | Q6: =EXACT(H6,M6) -> TRUE | R6: =EXACT(I6,N6) -> TRUE | S6: =EXACT(J6,O6) -> TRUE
A7: =_xlfn.XLOOKUP(B7,pratos!B:B,pratos!A:A,"não") -> 44 | B7: Abobrinha ao forno | C7: =_xlfn.XLOOKUP(D7,ingredientes!B:B,ingredientes!A:A,"não") -> 12 | D7: Abobrinha italiana refogada, sem sal | E7: 100 | H7: =A7 -> 44 | I7: =C7 -> 12 | J7: =E7 -> 100 | K7: =H7+I7 -> 56 | M7: 44 | N7: 12 | O7: 100 | Q7: =EXACT(H7,M7) -> TRUE | R7: =EXACT(I7,N7) -> TRUE | S7: =EXACT(J7,O7) -> TRUE
A8: =_xlfn.XLOOKUP(B8,pratos!B:B,pratos!A:A,"não") -> 45 | B8: Abobrinha com coentro | C8: =_xlfn.XLOOKUP(D8,ingredientes!B:B,ingredientes!A:A,"não") -> 10 | D8: Abobrinha italiana ensopada, sem sal | E8: 100 | H8: =A8 -> 45 | I8: =C8 -> 10 | J8: =E8 -> 100 | K8: =H8+I8 -> 55 | M8: 45 | N8: 10 | O8: 100 | Q8: =EXACT(H8,M8) -> TRUE | R8: =EXACT(I8,N8) -> TRUE | S8: =EXACT(J8,O8) -> TRUE
A9: =_xlfn.XLOOKUP(B9,pratos!B:B,pratos!A:A,"não") -> 45 | B9: Abobrinha com coentro | C9: =_xlfn.XLOOKUP(D9,ingredientes!B:B,ingredientes!A:A,"não") -> 150 | D9: Folha de coentro crua | E9: 5 | H9: =A9 -> 45 | I9: =C9 -> 150 | J9: =E9 -> 5 | K9: =H9+I9 -> 195 | M9: 45 | N9: 150 | O9: 5 | Q9: =EXACT(H9,M9) -> TRUE | R9: =EXACT(I9,N9) -> TRUE | S9: =EXACT(J9,O9) -> TRUE
A10: =_xlfn.XLOOKUP(B10,pratos!B:B,pratos!A:A,"não") -> 46 | B10: Abobrinha cozida | C10: =_xlfn.XLOOKUP(D10,ingredientes!B:B,ingredientes!A:A,"não") -> 10 | D10: Abobrinha italiana ensopada, sem sal | E10: 100 | H10: =A10 -> 46 | I10: =C10 -> 10 | J10: =E10 -> 100 | K10: =H10+I10 -> 56 | M10: 46 | N10: 10 | O10: 100 | Q10: =EXACT(H10,M10) -> TRUE | R10: =EXACT(I10,N10) -> TRUE | S10: =EXACT(J10,O10) -> TRUE
A11: =_xlfn.XLOOKUP(B11,pratos!B:B,pratos!A:A,"não") -> 47 | B11: Abobrinha em Lâminas com Bacon | C11: =_xlfn.XLOOKUP(D11,ingredientes!B:B,ingredientes!A:A,"não") -> 8 | D11: Abobrinha italiana cozida sem sal | E11: 90 | H11: =A11 -> 47 | I11: =C11 -> 8 | J11: =E11 -> 90 | K11: =H11+I11 -> 55 | M11: 47 | N11: 8 | O11: 90 | Q11: =EXACT(H11,M11) -> TRUE | R11: =EXACT(I11,N11) -> TRUE | S11: =EXACT(J11,O11) -> TRUE
A12: =_xlfn.XLOOKUP(B12,pratos!B:B,pratos!A:A,"não") -> 48 | B12: Abobrinha em Lâminas com tempero verde | C12: =_xlfn.XLOOKUP(D12,ingredientes!B:B,ingredientes!A:A,"não") -> 8 | D12: Abobrinha italiana cozida sem sal | E12: 100 | H12: =A12 -> 48 | I12: =C12 -> 8 | J12: =E12 -> 100 | K12: =H12+I12 -> 56 | Q12: =EXACT(H12,M12) -> FALSE | R12: =EXACT(I12,N12) -> FALSE | S12: =EXACT(J12,O12) -> FALSE
A13: =_xlfn.XLOOKUP(B13,pratos!B:B,pratos!A:A,"não") -> 48 | B13: Abobrinha em Lâminas com tempero verde | C13: =_xlfn.XLOOKUP(D13,ingredientes!B:B,ingredientes!A:A,"não") -> 8 | D13: Abobrinha italiana cozida sem sal | E13: 90 | H13: =A13 -> 48 | I13: =C13 -> 8 | J13: =E13 -> 90 | K13: =H13+I13 -> 56 | Q13: =EXACT(H13,M13) -> FALSE | R13: =EXACT(I13,N13) -> FALSE | S13: =EXACT(J13,O13) -> FALSE
A14: =_xlfn.XLOOKUP(B14,pratos!B:B,pratos!A:A,"não") -> 49 | B14: Abobrinha ensopada | C14: =_xlfn.XLOOKUP(D14,ingredientes!B:B,ingredientes!A:A,"não") -> 10 | D14: Abobrinha italiana ensopada, sem sal | E14: 100 | H14: =A14 -> 49 | I14: =C14 -> 10 | J14: =E14 -> 100 | K14: =H14+I14 -> 59 | M14: 49 | N14: 10 | O14: 100 | Q14: =EXACT(H14,M14) -> TRUE | R14: =EXACT(I14,N14) -> TRUE | S14: =EXACT(J14,O14) -> TRUE
A15: =_xlfn.XLOOKUP(B15,pratos!B:B,pratos!A:A,"não") -> 50 | B15: Abobrinha refogada | C15: =_xlfn.XLOOKUP(D15,ingredientes!B:B,ingredientes!A:A,"não") -> 12 | D15: Abobrinha italiana refogada, sem sal | E15: 100 | H15: =A15 -> 50 | I15: =C15 -> 12 | J15: =E15 -> 100 | K15: =H15+I15 -> 62 | M15: 50 | N15: 12 | O15: 100 | Q15: =EXACT(H15,M15) -> TRUE | R15: =EXACT(I15,N15) -> TRUE | S15: =EXACT(J15,O15) -> TRUE
A16: =_xlfn.XLOOKUP(B16,pratos!B:B,pratos!A:A,"não") -> 51 | B16: Acelga ao vinagrete | C16: =_xlfn.XLOOKUP(D16,ingredientes!B:B,ingredientes!A:A,"não") -> 14 | D16: Acelga | E16: 30 | H16: =A16 -> 51 | I16: =C16 -> 14 | J16: =E16 -> 30 | K16: =H16+I16 -> 65 | M16: 51 | N16: 14 | O16: 30 | Q16: =EXACT(H16,M16) -> TRUE | R16: =EXACT(I16,N16) -> TRUE | S16: =EXACT(J16,O16) -> TRUE
A17: =_xlfn.XLOOKUP(B17,pratos!B:B,pratos!A:A,"não") -> 51 | B17: Acelga ao vinagrete | C17: =_xlfn.XLOOKUP(D17,ingredientes!B:B,ingredientes!A:A,"não") -> 322 | D17: Vinagrete | E17: 70 | H17: =A17 -> 51 | I17: =C17 -> 322 | J17: =E17 -> 70 | K17: =H17+I17 -> 373 | M17: 51 | N17: 322 | O17: 70 | Q17: =EXACT(H17,M17) -> TRUE | R17: =EXACT(I17,N17) -> TRUE | S17: =EXACT(J17,O17) -> TRUE
A18: =_xlfn.XLOOKUP(B18,pratos!B:B,pratos!A:A,"não") -> 52 | B18: Acelga com pimentão colorido | C18: =_xlfn.XLOOKUP(D18,ingredientes!B:B,ingredientes!A:A,"não") -> 14 | D18: Acelga | E18: 30 | H18: =A18 -> 52 | I18: =C18 -> 14 | J18: =E18 -> 30 | K18: =H18+I18 -> 66 | M18: 52 | N18: 14 | O18: 30 | Q18: =EXACT(H18,M18) -> TRUE | R18: =EXACT(I18,N18) -> TRUE | S18: =EXACT(J18,O18) -> TRUE
A19: =_xlfn.XLOOKUP(B19,pratos!B:B,pratos!A:A,"não") -> 52 | B19: Acelga com pimentão colorido | C19: =_xlfn.XLOOKUP(D19,ingredientes!B:B,ingredientes!A:A,"não") -> 251 | D19: Pimentão amarelo | E19: 10 | H19: =A19 -> 52 | I19: =C19 -> 251 | J19: =E19 -> 10 | K19: =H19+I19 -> 303 | M19: 52 | N19: 251 | O19: 10 | Q19: =EXACT(H19,M19) -> TRUE | R19: =EXACT(I19,N19) -> TRUE | S19: =EXACT(J19,O19) -> TRUE
A20: =_xlfn.XLOOKUP(B20,pratos!B:B,pratos!A:A,"não") -> 52 | B20: Acelga com pimentão colorido | C20: =_xlfn.XLOOKUP(D20,ingredientes!B:B,ingredientes!A:A,"não") -> 252 | D20: Pimentão verde | E20: 10 | H20: =A20 -> 52 | I20: =C20 -> 252 | J20: =E20 -> 10 | K20: =H20+I20 -> 304 | M20: 52 | N20: 252 | O20: 10 | Q20: =EXACT(H20,M20) -> TRUE | R20: =EXACT(I20,N20) -> TRUE | S20: =EXACT(J20,O20) -> TRUE
A21: =_xlfn.XLOOKUP(B21,pratos!B:B,pratos!A:A,"não") -> 52 | B21: Acelga com pimentão colorido | C21: =_xlfn.XLOOKUP(D21,ingredientes!B:B,ingredientes!A:A,"não") -> 253 | D21: Pimentão vermelho | E21: 10 | H21: =A21 -> 52 | I21: =C21 -> 253 | J21: =E21 -> 10 | K21: =H21+I21 -> 305 | M21: 52 | N21: 253 | O21: 10 | Q21: =EXACT(H21,M21) -> TRUE | R21: =EXACT(I21,N21) -> TRUE | S21: =EXACT(J21,O21) -> TRUE
A22: =_xlfn.XLOOKUP(B22,pratos!B:B,pratos!A:A,"não") -> 53 | B22: Agrião com Tomate | C22: =_xlfn.XLOOKUP(D22,ingredientes!B:B,ingredientes!A:A,"não") -> 18 | D22: Agrião | E22: 30 | H22: =A22 -> 53 | I22: =C22 -> 18 | J22: =E22 -> 30 | K22: =H22+I22 -> 71 | M22: 53 | N22: 18 | O22: 30 | Q22: =EXACT(H22,M22) -> TRUE | R22: =EXACT(I22,N22) -> TRUE | S22: =EXACT(J22,O22) -> TRUE
A23: =_xlfn.XLOOKUP(B23,pratos!B:B,pratos!A:A,"não") -> 53 | B23: Agrião com tomate | C23: =_xlfn.XLOOKUP(D23,ingredientes!B:B,ingredientes!A:A,"não") -> 313 | D23: Tomate salada | E23: 70 | H23: =A23 -> 53 | I23: =C23 -> 313 | J23: =E23 -> 70 | K23: =H23+I23 -> 366 | M23: 53 | N23: 313 | O23: 70 | Q23: =EXACT(H23,M23) -> TRUE | R23: =EXACT(I23,N23) -> TRUE | S23: =EXACT(J23,O23) -> TRUE
A24: =_xlfn.XLOOKUP(B24,pratos!B:B,pratos!A:A,"não") -> 55 | B24: Água de coco | C24: =_xlfn.XLOOKUP(D24,ingredientes!B:B,ingredientes!A:A,"não") -> 20 | D24: Água de coco | E24: 160 | H24: =A24 -> 55 | I24: =C24 -> 20 | J24: =E24 -> 160 | K24: =H24+I24 -> 75 | M24: 55 | N24: 20 | O24: 160 | Q24: =EXACT(H24,M24) -> TRUE | R24: =EXACT(I24,N24) -> TRUE | S24: =EXACT(J24,O24) -> TRUE
A25: =_xlfn.XLOOKUP(B25,pratos!B:B,pratos!A:A,"não") -> 56 | B25: Aipim Cozido | C25: =_xlfn.XLOOKUP(D25,ingredientes!B:B,ingredientes!A:A,"não") -> 23 | D25: Aipim cozido, sem sal | E25: 100 | H25: =A25 -> 56 | I25: =C25 -> 23 | J25: =E25 -> 100 | K25: =H25+I25 -> 79 | M25: 56 | N25: 23 | O25: 100 | Q25: =EXACT(H25,M25) -> TRUE | R25: =EXACT(I25,N25) -> TRUE | S25: =EXACT(J25,O25) -> TRUE
... A625: =_xlfn.XLOOKUP(B625,pratos!B:B,pratos!A:A,"não") -> 419 | B625: Souflê de Legumes (Vagem, Cenoura e Chuchu) | C625: =_xlfn.XLOOKUP(D625,ingredientes!B:B,ingredientes!A:A,"não") -> 304 | D625: Souflê, sem sal | E625: 100 | H625: =A625 -> 419 | I625: =C625 -> 304 | J625: =E625 -> 100 | K625: =H625+I625 -> 723 | M625: 419 | N625: 304 | O625: 100 | Q625: =EXACT(H625,M625) -> TRUE | R625: =EXACT(I625,N625) -> TRUE | S625: =EXACT(J625,O625) -> TRUE
A626: =_xlfn.XLOOKUP(B626,pratos!B:B,pratos!A:A,"não") -> não | B626: Suco de acerola com adoçante | C626: =_xlfn.XLOOKUP(D626,ingredientes!B:B,ingredientes!A:A,"não") -> 258 | D626: Polpa de acerola congelada | E626: 50 | H626: =A626 -> não | I626: =C626 -> 258 | J626: =E626 -> 50 | K626: =H626+I626 -> #VALUE! | Q626: =EXACT(H626,M626) -> FALSE | R626: =EXACT(I626,N626) -> FALSE | S626: =EXACT(J626,O626) -> FALSE
A627: =_xlfn.XLOOKUP(B627,pratos!B:B,pratos!A:A,"não") -> 425 | B627: Suco de caju com adoçante | C627: =_xlfn.XLOOKUP(D627,ingredientes!B:B,ingredientes!A:A,"não") -> 259 | D627: Polpa de caju congelada | E627: 25 | H627: =A627 -> 425 | I627: =C627 -> 259 | J627: =E627 -> 25 | K627: =H627+I627 -> 684 | M627: 425 | N627: 259 | O627: 25 | Q627: =EXACT(H627,M627) -> TRUE | R627: =EXACT(I627,N627) -> TRUE | S627: =EXACT(J627,O627) -> TRUE
A628: =_xlfn.XLOOKUP(B628,pratos!B:B,pratos!A:A,"não") -> não | B628: Suco de graviola com adoçante | C628: =_xlfn.XLOOKUP(D628,ingredientes!B:B,ingredientes!A:A,"não") -> 261 | D628: Polpa de graviola congelada | E628: 50 | H628: =A628 -> não | I628: =C628 -> 261 | J628: =E628 -> 50 | K628: =H628+I628 -> #VALUE! | Q628: =EXACT(H628,M628) -> FALSE | R628: =EXACT(I628,N628) -> FALSE | S628: =EXACT(J628,O628) -> FALSE
A629: =_xlfn.XLOOKUP(B629,pratos!B:B,pratos!A:A,"não") -> não | B629: Suco de mamão com adoçante | C629: =_xlfn.XLOOKUP(D629,ingredientes!B:B,ingredientes!A:A,"não") -> 262 | D629: Polpa de mamão congelada | E629: 35 | H629: =A629 -> não | I629: =C629 -> 262 | J629: =E629 -> 35 | K629: =H629+I629 -> #VALUE! | Q629: =EXACT(H629,M629) -> FALSE | R629: =EXACT(I629,N629) -> FALSE | S629: =EXACT(J629,O629) -> FALSE
A630: =_xlfn.XLOOKUP(B630,pratos!B:B,pratos!A:A,"não") -> não | B630: Suco de manga com adoçante | C630: =_xlfn.XLOOKUP(D630,ingredientes!B:B,ingredientes!A:A,"não") -> 263 | D630: Polpa de manga congelada | E630: 50 | H630: =A630 -> não | I630: =C630 -> 263 | J630: =E630 -> 50 | K630: =H630+I630 -> #VALUE! | Q630: =EXACT(H630,M630) -> FALSE | R630: =EXACT(I630,N630) -> FALSE | S630: =EXACT(J630,O630) -> FALSE
A631: =_xlfn.XLOOKUP(B631,pratos!B:B,pratos!A:A,"não") -> 432 | B631: Suco de maracujá com adoçante | C631: =_xlfn.XLOOKUP(D631,ingredientes!B:B,ingredientes!A:A,"não") -> 265 | D631: Polpa de maracujá congelada | E631: 40 | H631: =A631 -> 432 | I631: =C631 -> 265 | J631: =E631 -> 40 | K631: =H631+I631 -> 697 | M631: 432 | N631: 265 | O631: 40 | Q631: =EXACT(H631,M631) -> TRUE | R631: =EXACT(I631,N631) -> TRUE | S631: =EXACT(J631,O631) -> TRUE
A632: =_xlfn.XLOOKUP(B632,pratos!B:B,pratos!A:A,"não") -> 422 | B632: Suco de acerola | C632: =_xlfn.XLOOKUP(D632,ingredientes!B:B,ingredientes!A:A,"não") -> 17 | D632: Açúcar cristal | E632: 20 | H632: =A632 -> 422 | I632: =C632 -> 17 | J632: =E632 -> 20 | K632: =H632+I632 -> 439 | M632: 422 | N632: 17 | O632: 20 | Q632: =EXACT(H632,M632) -> TRUE | R632: =EXACT(I632,N632) -> TRUE | S632: =EXACT(J632,O632) -> TRUE
A633: =_xlfn.XLOOKUP(B633,pratos!B:B,pratos!A:A,"não") -> 422 | B633: Suco de acerola | C633: =_xlfn.XLOOKUP(D633,ingredientes!B:B,ingredientes!A:A,"não") -> 258 | D633: Polpa de acerola congelada | E633: 50 | H633: =A633 -> 422 | I633: =C633 -> 258 | J633: =E633 -> 50 | K633: =H633+I633 -> 680 | M633: 422 | N633: 258 | O633: 50 | Q633: =EXACT(H633,M633) -> TRUE | R633: =EXACT(I633,N633) -> TRUE | S633: =EXACT(J633,O633) -> TRUE
A634: =_xlfn.XLOOKUP(B634,pratos!B:B,pratos!A:A,"não") -> 423 | B634: Suco de cajú | C634: =_xlfn.XLOOKUP(D634,ingredientes!B:B,ingredientes!A:A,"não") -> 259 | D634: Polpa de caju congelada | E634: 50 | H634: =A634 -> 423 | I634: =C634 -> 259 | J634: =E634 -> 50 | K634: =H634+I634 -> 682 | M634: 423 | N634: 259 | O634: 50 | Q634: =EXACT(H634,M634) -> TRUE | R634: =EXACT(I634,N634) -> TRUE | S634: =EXACT(J634,O634) -> TRUE
A635: =_xlfn.XLOOKUP(B635,pratos!B:B,pratos!A:A,"não") -> 423 | B635: Suco de cajú | C635: =_xlfn.XLOOKUP(D635,ingredientes!B:B,ingredientes!A:A,"não") -> 17 | D635: Açúcar cristal | E635: 10 | H635: =A635 -> 423 | I635: =C635 -> 17 | J635: =E635 -> 10 | K635: =H635+I635 -> 440 | M635: 423 | N635: 17 | O635: 10 | Q635: =EXACT(H635,M635) -> TRUE | R635: =EXACT(I635,N635) -> TRUE | S635: =EXACT(J635,O635) -> TRUE
A636: =_xlfn.XLOOKUP(B636,pratos!B:B,pratos!A:A,"não") -> 425 | B636: Suco de caju com adoçante | C636: =_xlfn.XLOOKUP(D636,ingredientes!B:B,ingredientes!A:A,"não") -> 259 | D636: Polpa de caju congelada | E636: 50 | H636: =A636 -> 425 | I636: =C636 -> 259 | J636: =E636 -> 50 | K636: =H636+I636 -> 684 | M636: 425 | N636: 259 | O636: =J636 -> 50 | Q636: =EXACT(H636,M636) -> TRUE | R636: =EXACT(I636,N636) -> TRUE | S636: =EXACT(J636,O636) -> TRUE
A637: =_xlfn.XLOOKUP(B637,pratos!B:B,pratos!A:A,"não") -> 426 | B637: Suco de graviola | C637: =_xlfn.XLOOKUP(D637,ingredientes!B:B,ingredientes!A:A,"não") -> 17 | D637: Açúcar cristal | E637: 10 | H637: =A637 -> 426 | I637: =C637 -> 17 | J637: =E637 -> 10 | K637: =H637+I637 -> 443 | Q637: =EXACT(H637,M637) -> FALSE | R637: =EXACT(I637,N637) -> FALSE | S637: =EXACT(J637,O637) -> FALSE
A638: =_xlfn.XLOOKUP(B638,pratos!B:B,pratos!A:A,"não") -> 426 | B638: Suco de graviola | C638: =_xlfn.XLOOKUP(D638,ingredientes!B:B,ingredientes!A:A,"não") -> 261 | D638: Polpa de graviola congelada | E638: 50 | H638: =A638 -> 426 | I638: =C638 -> 261 | J638: =E638 -> 50 | K638: =H638+I638 -> 687 | Q638: =EXACT(H638,M638) -> FALSE | R638: =EXACT(I638,N638) -> FALSE | S638: =EXACT(J638,O638) -> FALSE
A639: =_xlfn.XLOOKUP(B639,pratos!B:B,pratos!A:A,"não") -> 427 | B639: Suco de laranja com acerola | C639: =_xlfn.XLOOKUP(D639,ingredientes!B:B,ingredientes!A:A,"não") -> 17 | D639: Açúcar cristal | E639: 23 | H639: =A639 -> 427 | I639: =C639 -> 17 | J639: =E639 -> 23 | K639: =H639+I639 -> 444 | Q639: =EXACT(H639,M639) -> FALSE | R639: =EXACT(I639,N639) -> FALSE | S639: =EXACT(J639,O639) -> FALSE
...

Sheet check_pratos
A1: id_prato | B1: CARDAPIO
A2: =_xlfn.XLOOKUP(B2,pratos!B:B,pratos!A:A,"não") -> 39 | B2: Abacaxi
A3: =_xlfn.XLOOKUP(B3,pratos!B:B,pratos!A:A,"não") -> 40 | B3: Abóbora refogada
A4: =_xlfn.XLOOKUP(B4,pratos!B:B,pratos!A:A,"não") -> 41 | B4: Abóbora Sautée
A5: =_xlfn.XLOOKUP(B5,pratos!B:B,pratos!A:A,"não") -> 43 | B5: Abóbora Sautée com Bacon
A6: =_xlfn.XLOOKUP(B6,pratos!B:B,pratos!A:A,"não") -> 44 | B6: Abobrinha ao forno
A7: =_xlfn.XLOOKUP(B7,pratos!B:B,pratos!A:A,"não") -> 45 | B7: Abobrinha com coentro
A8: =_xlfn.XLOOKUP(B8,pratos!B:B,pratos!A:A,"não") -> 46 | B8: Abobrinha cozida
A9: =_xlfn.XLOOKUP(B9,pratos!B:B,pratos!A:A,"não") -> 47 | B9: Abobrinha em Lâminas com Bacon
A10: =_xlfn.XLOOKUP(B10,pratos!B:B,pratos!A:A,"não") -> 48 | B10: Abobrinha em Lâminas com tempero verde
A11: =_xlfn.XLOOKUP(B11,pratos!B:B,pratos!A:A,"não") -> 49 | B11: Abobrinha ensopada
A12: =_xlfn.XLOOKUP(B12,pratos!B:B,pratos!A:A,"não") -> 50 | B12: Abobrinha refogada
A13: =_xlfn.XLOOKUP(B13,pratos!B:B,pratos!A:A,"não") -> 51 | B13: Acelga ao vinagrete
... A361: =_xlfn.XLOOKUP(B361,pratos!B:B,pratos!A:A,"não") -> 447 | B361: Vitamina HPHC

Sheet composicao_pratos
A3: Rótulos de Linha | B3: Soma de PER_CAPITA
A4: Abacaxi | B4: 210
A5: 1 | B5: 100
A6: 2 | B6: 100
A7: 114 | B7: 10
A8: Abóbora refogada | B8: 150
A9: 6 | B9: 150
A10: Abóbora Sautée | B10: 100
A11: 6 | B11: 100
A12: Abóbora Sautée | B12: 100
A13: 6 | B13: 100
A14: Abóbora Sautée com Bacon | B14: 110
A15: 6 | B15: 100
A16: 44 | B16: 10
A17: Abobrinha ao forno | B17: 100
A18: 12 | B18: 100
A19: Abobrinha com coentro | B19: 105
A20: 10 | B20: 100
A21: 150 | B21: 5
A22: Abobrinha cozida | B22: 100
A23: 10 | B23: 100
A24: Abobrinha em Lâminas com Bacon | B24: 90
A25: 8 | B25: 90
A26: Abobrinha em Lâminas com tempero verde | B26: 205
A27: 8 | B27: 190
A28: 94 | B28: 15
A29: Abobrinha ensopada | B29: 100
A30: 10 | B30: 100
A31: Abobrinha refogada | B31: 150
A32: 12 | B32: 150
A33: Acelga ao vinagrete | B33: 130
A34: 14 | B34: 30
A35: 322 | B35: 100
A36: Acelga com pimentão colorido | B36: 80
A37: 14 | B37: 50
A38: 251 | B38: 10
A39: 252 | B39: 10
A40: 253 | B40: 10
A41: Agrião com Tomate | B41: 280
A42: 18 | B42: 90
...

Sheet Planilha5

Sheet pratos
A1: id | B1: nome_prato
A2: 39 | B2: Abacaxi
A3: 40 | B3: Abóbora refogada
A4: 41 | B4: Abóbora Sautée
A5: 42 | B5: Abóbora Sautée
A6: 43 | B6: Abóbora Sautée com Bacon
A7: 44 | B7: Abobrinha ao forno
A8: 45 | B8: Abobrinha com coentro
A9: 46 | B9: Abobrinha cozida
A10: 47 | B10: Abobrinha em Lâminas com Bacon
A11: 48 | B11: Abobrinha em Lâminas com tempero verde
A12: 49 | B12: Abobrinha ensopada
A13: 50 | B13: Abobrinha refogada
... A410: 447 | B410: Vitamina HPHC

Sheet ingredientes
A1: id | B1: nome
A2: 1 | B2: Abacaxi
A3: 2 | B3: Abacaxi cru
A4: 4 | B4: Abóbora cozida drenada, com sal
A5: 3 | B5: Abóbora cozida sem sal
A6: 5 | B6: Abóbora moranga refogada, com sal
A7: 6 | B7: Abóbora moranga refogada, sem sal
A8: 7 | B8: Abobrinha italiana cozida com sal
A9: 8 | B9: Abobrinha italiana cozida sem sal
A10: 11 | B10: Abobrinha italiana cozida, com sal
A11: 9 | B11: Abobrinha italiana ensopada, com sal
A12: 10 | B12: Abobrinha italiana ensopada, sem sal
A13: 13 | B13: Abobrinha italiana refogada, com sal
... A324: 323 | B324: Vitamina HPHC

Sheet pratos_hospital
A1: CARDAPIO
A2: Abacaxi
A3: Abóbora refogada
A4: Abóbora Sautée
A5: Abóbora Sautée
A6: Abóbora Sautée com Bacon
A7: Abobrinha ao forno
A8: Abobrinha com coentro
A9: Abobrinha cozida
A10: Abobrinha em Lâminas com Bacon
A11: Abobrinha em Lâminas com tempero verde
A12: Abobrinha ensopada
... A410: Vitamina HPHC

Sheet tamanho_porcoes
A1: alimento | B1: quantidade_g | C1: tipo_preparacao | D1: tipo_preparacao
A2: Abacaxi | B2: 210 | C2: FT - Fruta | D2: =_xlfn.XLOOKUP(C2,tipo_preparacoes!$B$2:$B$12,tipo_preparacoes!$A$2:$A$12,"não") -> 3
A3: Abóbora refogada | B3: 150 | C3: SD - Guarnição | D3: =_xlfn.XLOOKUP(C3,tipo_preparacoes!$B$2:$B$12,tipo_preparacoes!$A$2:$A$12,"não") -> 8
A4: Abóbora Sautée | B4: 100 | C4: SD - Guarnição | D4: =_xlfn.XLOOKUP(C4,tipo_preparacoes!$B$2:$B$12,tipo_preparacoes!$A$2:$A$12,"não") -> 8
A5: Abóbora Sautée | B5: 100 | C5: SD - Guarnição | D5: =_xlfn.XLOOKUP(C5,tipo_preparacoes!$B$2:$B$12,tipo_preparacoes!$A$2:$A$12,"não") -> 8
A6: Abóbora Sautée com Bacon | B6: 110 | C6: SD - Guarnição | D6: =_xlfn.XLOOKUP(C6,tipo_preparacoes!$B$2:$B$12,tipo_preparacoes!$A$2:$A$12,"não") -> 8
A7: Abobrinha ao forno | B7: 100 | C7: SD - Guarnição | D7: =_xlfn.XLOOKUP(C7,tipo_preparacoes!$B$2:$B$12,tipo_preparacoes!$A$2:$A$12,"não") -> 8
A8: Abobrinha com coentro | B8: 105 | C8: SD - Guarnição | D8: =_xlfn.XLOOKUP(C8,tipo_preparacoes!$B$2:$B$12,tipo_preparacoes!$A$2:$A$12,"não") -> 8
A9: Abobrinha cozida | B9: 100 | C9: SD - Guarnição | D9: =_xlfn.XLOOKUP(C9,tipo_preparacoes!$B$2:$B$12,tipo_preparacoes!$A$2:$A$12,"não") -> 8
A10: Abobrinha em Lâminas com Bacon | B10: 90 | C10: SD - Guarnição | D10: =_xlfn.XLOOKUP(C10,tipo_preparacoes!$B$2:$B$12,tipo_preparacoes!$A$2:$A$12,"não") -> 8
A11: Abobrinha em Lâminas com tempero verde | B11: 205 | C11: SD - Guarnição | D11: =_xlfn.XLOOKUP(C11,tipo_preparacoes!$B$2:$B$12,tipo_preparacoes!$A$2:$A$12,"não") -> 8
A12: Abobrinha ensopada | B12: 100 | C12: SD - Guarnição | D12: =_xlfn.XLOOKUP(C12,tipo_preparacoes!$B$2:$B$12,tipo_preparacoes!$A$2:$A$12,"não") -> 8
A13: Abobrinha refogada | B13: 150 | C13: SD - Guarnição | D13: =_xlfn.XLOOKUP(C13,tipo_preparacoes!$B$2:$B$12,tipo_preparacoes!$A$2:$A$12,"não") -> 8
... A410: Vitamina HPHC | B410: 320 | C410: SD - Guarnição | D410: =_xlfn.XLOOKUP(C410,tipo_preparacoes!$B$2:$B$12,tipo_preparacoes!$A$2:$A$12,"não") -> 8

Sheet tipo_preparacoes
A1: id | B1: nome
A2: 1 | B2: BC1 - Cereal (Café)
A3: 2 | B3: DP - Laticínios
A4: 3 | B4: FT - Fruta
A5: 4 | B5: RC - Arroz
A6: 5 | B6: BE - Feijão
A7: 6 | B7: EN - Entrada
A8: 7 | B8: MD - Principal (Carne)
A9: 8 | B9: SD - Guarnição
A10: 9 | B10: JC - Suco
A11: 10 | B11: DS - Sobremesa
A12: 11 | B12: BC2 - Cereal (Almoço)
